<?xml version='1.0'?>

<robot name="my_robot" xmlns:xacro="http://www.ros.org/wiki/xacro">

<xacro:include filename="$(find my_robot)/urdf/my_robot.gazebo" />

  <gazebo reference="left_wheel">
    <material>Gazebo/FlatBlack</material>
  </gazebo>
  <gazebo reference="right_wheel">
    <material>Gazebo/FlatBlack</material>
  </gazebo>
  <gazebo reference="chassis">
    <material>Gazebo/Red</material>
  </gazebo>
  <gazebo reference="camera">
    <material>Gazebo/Blue</material>
  </gazebo>

  <gazebo reference="front_caster">
    <mu1>0.0</mu1>
    <mu2>0.0</mu2>
    <material>Gazebo/RedBright</material>
  </gazebo>

  <gazebo reference="rear_caster">
    <mu1>0.0</mu1>
    <mu2>0.0</mu2>
    <material>Gazebo/RedBright</material>
  </gazebo>


  <link name="robot_footprint"></link>

  <joint name="robot_footprint_joint" type="fixed">
    <origin xyz="0 0 0" rpy="0 0 0" />
    <parent link="robot_footprint"/>
    <child link="chassis" />
  </joint>

  <link name='chassis'>
    <pose>0 0 0.2 0 0 0</pose>

    <inertial>
      <mass value="15.0"/>
      <origin xyz="0.0 0 0" rpy=" 0 0 0"/>
      <inertia
          ixx="0.1" ixy="0" ixz="0"
          iyy="0.1" iyz="0"
          izz="0.1"
      />
    </inertial>

    <collision name='collision'>
      <origin xyz="0 0 0" rpy=" 0 0 0"/> 
      <geometry>
        <box size=".5 .3 .2"/>
      </geometry>
    </collision>

    <visual name='chassis_visual'>
      <origin xyz="0 0 0" rpy=" 0 0 0"/>
      <geometry>
        <box size=".5 .3 .2"/>
      </geometry>
    </visual>

  </link>

  <link name="front_caster">

    <inertial>
      <mass value="0.1"/>
      <origin xyz="0 0 0" rpy="0 0 0"/>
      <inertia 
	  ixx="1e-6" ixy="0" ixz="0"
	  iyy="1e-6" iyz="0"
	  izz="1e-6"/>
    </inertial>

    <collision name='front_caster_collision'>
      <origin xyz="0 0 0" rpy=" 0 0 0"/>
      <geometry>
        <sphere radius="0.0999"/>
      </geometry>
    </collision>

    <visual name='front_caster_visual'>
      <origin xyz="0 0 0" rpy=" 0 0 0"/>
      <geometry>
        <sphere radius="0.1"/>
      </geometry>
    </visual>
  </link>

  <joint type="fixed" name="front_caster_joint">
    <origin xyz="0.15 0 -0.1" rpy="0 0 0"/>
    <parent link="chassis"/>
    <child link="front_caster"/>
    <axis xyz="0 1 0" rpy="0 0 0"/>
  </joint>


  <link name="rear_caster">

    <inertial>
      <mass value="0.1"/>
      <origin xyz="0 0 0" rpy="0 0 0"/>
      <inertia 
	  ixx="1e-6" ixy="0" ixz="0"
	  iyy="1e-6" iyz="0"
	  izz="1e-6"/>
    </inertial>

    <collision name='rear_caster_collision'>
      <origin xyz="0 0 0" rpy=" 0 0 0"/>
      <geometry>
        <sphere radius="0.0999"/>
      </geometry>
    </collision>

    <visual name='rear_caster_visual'>
      <origin xyz="0 0 0" rpy=" 0 0 0"/>
      <geometry>
        <sphere radius="0.1"/>
      </geometry>
    </visual>
  </link>

  <joint type="fixed" name="rear_caster_joint">
    <origin xyz="-0.15 0 -0.1" rpy="0 0 0"/>
    <parent link="chassis"/>
    <child link="rear_caster"/>
    <axis xyz="0 1 0" rpy="0 0 0"/>
  </joint>


  <link name='left_wheel'>
    <inertial>
      <mass value="5"/>
      <origin xyz="0 0 0" rpy="0 1.5707 1.5707"/>
      <inertia 
	  ixx="0.1" ixy="0" ixz="0"
	  iyy="0.1" iyz="0"
	  izz="0.1"/>
    </inertial>

    <collision name='left_wheel_collision'>
      <origin xyz="0 0 0" rpy="0 1.5707 1.5707"/>
      <geometry>
	<cylinder radius="0.2" length="0.1"/>
      </geometry>
    </collision>

    <visual name='left_wheel_visual'>
      <origin xyz="0 0 0" rpy="0 1.5707 1.5707"/>
      <geometry>
	<cylinder radius="0.2" length="0.1"/> 
      </geometry>
    </visual>
  </link>

  <joint type="continuous" name="left_wheel_hinge">
    <origin xyz="0 0.22 0" rpy="0 0 0"/>
    <child link="left_wheel"/>
    <parent link="chassis"/>
    <axis xyz="0 1 0" rpy="0 0 0"/>
    <limit effort="10000" velocity="1000"/>
    <dynamics damping="0.2" friction="0.2"/>
  </joint>


  <link name='right_wheel'>
    <inertial>
      <mass value="5"/>
      <origin xyz="0 0 0" rpy="0 1.5707 1.5707"/>
      <inertia 
	  ixx="0.1" ixy="0" ixz="0"
	  iyy="0.1" iyz="0"
	  izz="0.1"/>
    </inertial>

    <collision name='right_wheel_collision'>
      <origin xyz="0 0 0" rpy="0 1.5707 1.5707"/>
      <geometry>
	<cylinder radius="0.2" length="0.1"/> 
      </geometry>
    </collision>

    <visual name='right_wheel_visual'>
      <origin xyz="0 0 0" rpy="0 1.5707 1.5707"/>
      <geometry>
	<cylinder radius="0.2" length="0.1"/>
      </geometry>
    </visual>

  </link>

  <joint type="continuous" name="right_wheel_hinge">
    <origin xyz="0 -0.22 0" rpy="0 0 0"/>
    <child link="right_wheel"/>
    <parent link="chassis"/>
    <axis xyz="0 1 0" rpy="0 0 0"/>
    <limit effort="10000" velocity="1000"/>
    <dynamics damping="0.2" friction="0.2"/>
  </joint>

  <link name='camera'>
    <inertial>
      <mass value="0.1"/>
      <origin xyz="0 0 0" rpy="0 0 0"/>
      <inertia 
	  ixx="1e-6" ixy="0" ixz="0"
	  iyy="1e-6" iyz="0"
	  izz="1e-6"/>
    </inertial>

    <collision name='camera_collision'>
      <origin xyz="0 0 0" rpy="0 0 0"/>
      <geometry>
	<box size="0.05 0.05 0.05"/>
      </geometry>
    </collision>

    <visual name='camera_visual'>
      <origin xyz="0 0 0" rpy="0 0 0"/>
      <geometry>
	<box size="0.05 0.05 0.05"/>
      </geometry>
    </visual>

  </link>

  <joint type="fixed" name="camera_joint">
    <origin xyz="0.3 0 0" rpy="0 0 0"/>
    <child link="camera"/>
    <parent link="chassis"/>
    <axis xyz="0 1 0" rpy="0 0 0"/>
  </joint>

  <link name="hokuyo">
    <inertial>
      <mass value="1e-5"/>
      <origin xyz="0 0 0" rpy="0 0 0"/>
      <inertia 
	  ixx="1e-6" ixy="0" ixz="0"
	  iyy="1e-6" iyz="0"
	  izz="1e-6"/>
    </inertial>
    <collision>
      <origin xyz="0 0 0" rpy="0 0 0"/>
      <geometry>
	<box size="0.1 0.1 0.1"/>
      </geometry>
    </collision>
    <visual>
      <origin xyz="0 0 0" rpy="0 0 0"/>
      <geometry>
	<mesh filename = "package://my_robot/meshes/hokuyo.dae"/>
      </geometry>
    </visual>
  </link>

  <joint type="fixed" name="hokuyo_joint">
    <origin xyz="0.15 0 0.1" rpy="0 0 0"/>
    <parent link="chassis"/>
    <child link="hokuyo"/>
    <axis xyz="0 1 0" rpy="0 0 0"/>
  </joint>

</robot>


